Workbook
Name Cosumo_Negocio: Consumo!$A$1:$J$2746

Sheet Productos
A1: Código | B1: Producto | C1: Tipo | D1: Precio Neto | E1: IVA Dev | F1: Precio Venta | G1: Costo Unit | H1: Utilidad | I1: Margen
A2: TO-01 | B2: Toalla 160x80 Az | C2: Toalla | D2: 8992 | E2: =ROUND(Productos[[#This Row],[Precio Neto]]*0.19,0) -> 1708 | F2: =Productos[[#This Row],[Precio Neto]]+Productos[[#This Row],[IVA Dev]] -> 10700 | G2: =IFERROR(SUMIF('Receta'!$A$2:$A$266,Productos!A2,'Receta'!$K$2:$K$266),"") -> 6007.185 | H2: =IFERROR(Productos!$F2-Productos!$G2,"") -> 4692.815 | I2: =IFERROR(Productos!$H2/Productos!$G2,"") -> 0.78120035
A3: TO-02 | B3: Toalla 160x80 Ro | C3: Toalla | D3: 8992 | E3: =ROUND(Productos[[#This Row],[Precio Neto]]*0.19,0) -> 1708 | F3: =Productos[[#This Row],[Precio Neto]]+Productos[[#This Row],[IVA Dev]] -> 10700 | G3: =IFERROR(SUMIF('Receta'!$A$2:$A$266,Productos!A3,'Receta'!$K$2:$K$266),"") -> 5927.56 | H3: =IFERROR(Productos!$F3-Productos!$G3,"") -> 4772.44 | I3: =IFERROR(Productos!$H3/Productos!$G3,"") -> 0.80512724
A4: TO-03 | B4: Toalla 160x80 Am | C4: Toalla | D4: 8992 | E4: =ROUND(Productos[[#This Row],[Precio Neto]]*0.19,0) -> 1708 | F4: =Productos[[#This Row],[Precio Neto]]+Productos[[#This Row],[IVA Dev]] -> 10700 | G4: =IFERROR(SUMIF('Receta'!$A$2:$A$266,Productos!A4,'Receta'!$K$2:$K$266),"") -> 5927.56 | H4: =IFERROR(Productos!$F4-Productos!$G4,"") -> 4772.44 | I4: =IFERROR(Productos!$H4/Productos!$G4,"") -> 0.80512724
A5: TO-04 | B5: Toalla 160x80 Vp | C5: Toalla | D5: 8992 | E5: =ROUND(Productos[[#This Row],[Precio Neto]]*0.19,0) -> 1708 | F5: =Productos[[#This Row],[Precio Neto]]+Productos[[#This Row],[IVA Dev]] -> 10700 | G5: =IFERROR(SUMIF('Receta'!$A$2:$A$266,Productos!A5,'Receta'!$K$2:$K$266),"") -> 5927.56 | H5: =IFERROR(Productos!$F5-Productos!$G5,"") -> 4772.44 | I5: =IFERROR(Productos!$H5/Productos!$G5,"") -> 0.80512724
A6: TO-05 | B6: Toalla 160x80 Ca | C6: Toalla | D6: 8992 | E6: =ROUND(Productos[[#This Row],[Precio Neto]]*0.19,0) -> 1708 | F6: =Productos[[#This Row],[Precio Neto]]+Productos[[#This Row],[IVA Dev]] -> 10700 | G6: =IFERROR(SUMIF('Receta'!$A$2:$A$266,Productos!A6,'Receta'!$K$2:$K$266),"") -> 5927.56 | H6: =IFERROR(Productos!$F6-Productos!$G6,"") -> 4772.44 | I6: =IFERROR(Productos!$H6/Productos!$G6,"") -> 0.80512724
A7: TO-06 | B7: Toalla 160x80 Fu | C7: Toalla | D7: 8992 | E7: =ROUND(Productos[[#This Row],[Precio Neto]]*0.19,0) -> 1708 | F7: =Productos[[#This Row],[Precio Neto]]+Productos[[#This Row],[IVA Dev]] -> 10700 | G7: =IFERROR(SUMIF('Receta'!$A$2:$A$266,Productos!A7,'Receta'!$K$2:$K$266),"") -> 5927.56 | H7: =IFERROR(Productos!$F7-Productos!$G7,"") -> 4772.44 | I7: =IFERROR(Productos!$H7/Productos!$G7,"") -> 0.80512724
A8: TO-07 | B8: Toalla 160x80 Na | C8: Toalla | D8: 8992 | E8: =ROUND(Productos[[#This Row],[Precio Neto]]*0.19,0) -> 1708 | F8: =Productos[[#This Row],[Precio Neto]]+Productos[[#This Row],[IVA Dev]] -> 10700 | G8: =IFERROR(SUMIF('Receta'!$A$2:$A$266,Productos!A8,'Receta'!$K$2:$K$266),"") -> 5927.56 | H8: =IFERROR(Productos!$F8-Productos!$G8,"") -> 4772.44 | I8: =IFERROR(Productos!$H8/Productos!$G8,"") -> 0.80512724
A9: TO-08 | B9: Toalla 160x80 Ne | C9: Toalla | D9: 8992 | E9: =ROUND(Productos[[#This Row],[Precio Neto]]*0.19,0) -> 1708 | F9: =Productos[[#This Row],[Precio Neto]]+Productos[[#This Row],[IVA Dev]] -> 10700 | G9: =IFERROR(SUMIF('Receta'!$A$2:$A$266,Productos!A9,'Receta'!$K$2:$K$266),"") -> 5927.56 | H9: =IFERROR(Productos!$F9-Productos!$G9,"") -> 4772.44 | I9: =IFERROR(Productos!$H9/Productos!$G9,"") -> 0.80512724
A10: TO-09 | B10: Toalla 80x40 Na | C10: Toalla | D10: 7983 | E10: =ROUND(Productos[[#This Row],[Precio Neto]]*0.19,0) -> 1517 | F10: =Productos[[#This Row],[Precio Neto]]+Productos[[#This Row],[IVA Dev]] -> 9500 | G10: =IFERROR(SUMIF('Receta'!$A$2:$A$266,Productos!A10,'Receta'!$K$2:$K$266),"") -> 2226.89 | H10: =IFERROR(Productos!$F10-Productos!$G10,"") -> 7273.11 | I10: =IFERROR(Productos!$H10/Productos!$G10,"") -> 3.2660392
A11: TO-10 | B11: Toalla 40x40 Na | C11: Toalla | D11: 3782 | E11: =ROUND(Productos[[#This Row],[Precio Neto]]*0.19,0) -> 719 | F11: =Productos[[#This Row],[Precio Neto]]+Productos[[#This Row],[IVA Dev]] -> 4501 | G11: =IFERROR(SUMIF('Receta'!$A$2:$A$266,Productos!A11,'Receta'!$K$2:$K$266),"") -> 1465.945 | H11: =IFERROR(Productos!$F11-Productos!$G11,"") -> 3035.055 | I11: =IFERROR(Productos!$H11/Productos!$G11,"") -> 2.0703744
A12: TO-11 | B12: Toalla 160x110 Na | C12: Toalla | D12: 11092 | E12: =ROUND(Productos[[#This Row],[Precio Neto]]*0.19,0) -> 2107 | F12: =Productos[[#This Row],[Precio Neto]]+Productos[[#This Row],[IVA Dev]] -> 13199 | G12: =IFERROR(SUMIF('Receta'!$A$2:$A$266,Productos!A12,'Receta'!$K$2:$K$266),"") -> 8696.34 | H12: =IFERROR(Productos!$F12-Productos!$G12,"") -> 4502.66 | I12: =IFERROR(Productos!$H12/Productos!$G12,"") -> 0.51776494
A13: TO-12 | B13: Toalla 160x110 Li | C13: Toalla | D13: 11092 | E13: =ROUND(Productos[[#This Row],[Precio Neto]]*0.19,0) -> 2107 | F13: =Productos[[#This Row],[Precio Neto]]+Productos[[#This Row],[IVA Dev]] -> 13199 | G13: =IFERROR(SUMIF('Receta'!$A$2:$A$266,Productos!A13,'Receta'!$K$2:$K$266),"") -> 6161.34 | H13: =IFERROR(Productos!$F13-Productos!$G13,"") -> 7037.66 | I13: =IFERROR(Productos!$H13/Productos!$G13,"") -> 1.1422288
... A23: TU-08 | B23: Turbante Ro | C23: Turbante | D23: 4706 | E23: =ROUND(Productos[[#This Row],[Precio Neto]]*0.19,0) -> 894 | F23: =Productos[[#This Row],[Precio Neto]]+Productos[[#This Row],[IVA Dev]] -> 5600 | G23: =IFERROR(SUMIF('Receta'!$A$2:$A$266,Productos!A23,'Receta'!$K$2:$K$266),"") -> 1498.3363 | H23: =IFERROR(Productos!$F23-Productos!$G23,"") -> 4101.6637 | I23: =IFERROR(Productos!$H23/Productos!$G23,"") -> 2.7374788
D24: 0 | E24: =ROUND(Productos[[#This Row],[Precio Neto]]*0.19,0) -> 0 | F24: =Productos[[#This Row],[Precio Neto]]+Productos[[#This Row],[IVA Dev]] -> 0 | G24: =IFERROR(SUMIF('Receta'!$A$2:$A$266,Productos!A24,'Receta'!$K$2:$K$266),"") -> 0 | H24: =IFERROR(Productos!$F24-Productos!$G24,"") -> 0 | I24: =IFERROR(Productos!$H24/Productos!$G24,"")

Sheet Materias Primas
A1: Código | B1: Materia Prima | C1: Tipo | D1: Cantidad | E1: Unidad | F1: Costo Neto | G1: IVA Cred | H1: Costo Base | I1: Costo Ref | J1: CU
A2: TE-01 | B2: Microfibra Dep 160 Na | C2: MP | D2: 1 | E2: Mts | F2: 4118 | G2: =ROUND(Materias_Primas[[#This Row],[Costo Neto]]*0.19,0) -> 782 | H2: =Materias_Primas[[#This Row],[Costo Neto]]+Materias_Primas[[#This Row],[IVA Cred]] -> 4900 | I2: {=MAX(IF(Compras!$F$11:$F$155='Materias Primas'!$A2,Compras!$M$11:$M$155,'Materias Primas'!$H2))} -> 4900 | J2: =IFERROR(ROUND(I2/D2,0),"") -> 4900
A3: TE-02 | B3: Microfibra Dep 160 Li | C3: MP | D3: 1 | E3: Mts | F3: 4118 | G3: =ROUND(Materias_Primas[[#This Row],[Costo Neto]]*0.19,0) -> 782 | H3: =Materias_Primas[[#This Row],[Costo Neto]]+Materias_Primas[[#This Row],[IVA Cred]] -> 4900 | I3: {=MAX(IF(Compras!$F$11:$F$155='Materias Primas'!$A3,Compras!$M$11:$M$155,'Materias Primas'!$H3))} -> 4900 | J3: =IFERROR(ROUND(I3/D3,0),"") -> 4900
A4: TE-03 | B4: Microfibra Dep 160 Fu | C4: MP | D4: 1 | E4: Mts | F4: 4118 | G4: =ROUND(Materias_Primas[[#This Row],[Costo Neto]]*0.19,0) -> 782 | H4: =Materias_Primas[[#This Row],[Costo Neto]]+Materias_Primas[[#This Row],[IVA Cred]] -> 4900 | I4: {=MAX(IF(Compras!$F$11:$F$155='Materias Primas'!$A4,Compras!$M$11:$M$155,'Materias Primas'!$H4))} -> 4900 | J4: =IFERROR(ROUND(I4/D4,0),"") -> 4900
A5: TE-04 | B5: Microfibra Dep 160 Ca | C5: MP | D5: 1 | E5: Mts | F5: 4118 | G5: =ROUND(Materias_Primas[[#This Row],[Costo Neto]]*0.19,0) -> 782 | H5: =Materias_Primas[[#This Row],[Costo Neto]]+Materias_Primas[[#This Row],[IVA Cred]] -> 4900 | I5: {=MAX(IF(Compras!$F$11:$F$155='Materias Primas'!$A5,Compras!$M$11:$M$155,'Materias Primas'!$H5))} -> 4900 | J5: =IFERROR(ROUND(I5/D5,0),"") -> 4900
A6: TE-05 | B6: Microfibra Dep 160 Ne | C6: MP | D6: 1 | E6: Mts | F6: 4118 | G6: =ROUND(Materias_Primas[[#This Row],[Costo Neto]]*0.19,0) -> 782 | H6: =Materias_Primas[[#This Row],[Costo Neto]]+Materias_Primas[[#This Row],[IVA Cred]] -> 4900 | I6: {=MAX(IF(Compras!$F$11:$F$155='Materias Primas'!$A6,Compras!$M$11:$M$155,'Materias Primas'!$H6))} -> 4900 | J6: =IFERROR(ROUND(I6/D6,0),"") -> 4900
A7: TE-06 | B7: Microfibra Dep 160 Am | C7: MP | D7: 1 | E7: Mts | F7: 4118 | G7: =ROUND(Materias_Primas[[#This Row],[Costo Neto]]*0.19,0) -> 782 | H7: =Materias_Primas[[#This Row],[Costo Neto]]+Materias_Primas[[#This Row],[IVA Cred]] -> 4900 | I7: {=MAX(IF(Compras!$F$11:$F$155='Materias Primas'!$A7,Compras!$M$11:$M$155,'Materias Primas'!$H7))} -> 4900 | J7: =IFERROR(ROUND(I7/D7,0),"") -> 4900
A8: TE-07 | B8: Microfibra Dep 160 Ro | C8: MP | D8: 1 | E8: Mts | F8: 4118 | G8: =ROUND(Materias_Primas[[#This Row],[Costo Neto]]*0.19,0) -> 782 | H8: =Materias_Primas[[#This Row],[Costo Neto]]+Materias_Primas[[#This Row],[IVA Cred]] -> 4900 | I8: {=MAX(IF(Compras!$F$11:$F$155='Materias Primas'!$A8,Compras!$M$11:$M$155,'Materias Primas'!$H8))} -> 4900 | J8: =IFERROR(ROUND(I8/D8,0),"") -> 4900
A9: TE-08 | B9: Microfibra Dep 160 Vp | C9: MP | D9: 1 | E9: Mts | F9: 4118 | G9: =ROUND(Materias_Primas[[#This Row],[Costo Neto]]*0.19,0) -> 782 | H9: =Materias_Primas[[#This Row],[Costo Neto]]+Materias_Primas[[#This Row],[IVA Cred]] -> 4900 | I9: {=MAX(IF(Compras!$F$11:$F$155='Materias Primas'!$A9,Compras!$M$11:$M$155,'Materias Primas'!$H9))} -> 4900 | J9: =IFERROR(ROUND(I9/D9,0),"") -> 4900
A10: TE-09 | B10: Microfibra Dep 160 Az | C10: MP | D10: 1 | E10: Mts | F10: 4118 | G10: =ROUND(Materias_Primas[[#This Row],[Costo Neto]]*0.19,0) -> 782 | H10: =Materias_Primas[[#This Row],[Costo Neto]]+Materias_Primas[[#This Row],[IVA Cred]] -> 4900 | I10: {=MAX(IF(Compras!$F$11:$F$155='Materias Primas'!$A10,Compras!$M$11:$M$155,'Materias Primas'!$H10))} -> 4900 | J10: =IFERROR(ROUND(I10/D10,0),"") -> 4900
A11: TE-10 | B11: Bistrech 150 cm Ne | C11: MP | D11: 1 | E11: Mts | F11: 655 | G11: =ROUND(Materias_Primas[[#This Row],[Costo Neto]]*0.19,0) -> 124 | H11: =Materias_Primas[[#This Row],[Costo Neto]]+Materias_Primas[[#This Row],[IVA Cred]] -> 779 | I11: {=MAX(IF(Compras!$F$11:$F$155='Materias Primas'!$A11,Compras!$M$11:$M$155,'Materias Primas'!$H11))} -> 779 | J11: =IFERROR(ROUND(I11/D11,0),"") -> 779
A12: TE-11 | B12: Bistrech 300 cm Ne | C12: MP | D12: 1 | E12: Mts | F12: 1597 | G12: =ROUND(Materias_Primas[[#This Row],[Costo Neto]]*0.19,0) -> 303 | H12: =Materias_Primas[[#This Row],[Costo Neto]]+Materias_Primas[[#This Row],[IVA Cred]] -> 1900 | I12: {=MAX(IF(Compras!$F$11:$F$155='Materias Primas'!$A12,Compras!$M$11:$M$155,'Materias Primas'!$H12))} -> 1900 | J12: =IFERROR(ROUND(I12/D12,0),"") -> 1900
A13: TE-12 | B13: Mantel Spandex 180 Ne | C13: PT | D13: 1 | E13: Uni | F13: 0 | G13: =ROUND(Materias_Primas[[#This Row],[Costo Neto]]*0.19,0) -> 0 | H13: =Materias_Primas[[#This Row],[Costo Neto]]+Materias_Primas[[#This Row],[IVA Cred]] -> 0 | I13: {=MAX(IF(Compras!$F$11:$F$155='Materias Primas'!$A13,Compras!$M$11:$M$155,'Materias Primas'!$H13))} -> 0 | J13: =IFERROR(ROUND(I13/D13,0),"") -> 0
... A29: HI-03 | B29: Hilo Poliester | C29: MP | D29: 1 | E29: Uni | F29: 748 | G29: =ROUND(Materias_Primas[[#This Row],[Costo Neto]]*0.19,0) -> 142 | H29: =Materias_Primas[[#This Row],[Costo Neto]]+Materias_Primas[[#This Row],[IVA Cred]] -> 890 | I29: {=MAX(IF(Compras!$F$11:$F$155='Materias Primas'!$A29,Compras!$M$11:$M$155,'Materias Primas'!$H29))} -> 890 | J29: =IFERROR(ROUND(I29/D29,0),"") -> 890
F30: 0 | G30: =ROUND(Materias_Primas[[#This Row],[Costo Neto]]*0.19,0) -> 0 | H30: =Materias_Primas[[#This Row],[Costo Neto]]+Materias_Primas[[#This Row],[IVA Cred]] -> 0 | I30: {=MAX(IF(Compras!$F$11:$F$155='Materias Primas'!$A30,Compras!$M$11:$M$155,'Materias Primas'!$H30))} -> 0 | J30: =IFERROR(ROUND(I30/D30,0),"")
F31: 0 | G31: =ROUND(Materias_Primas[[#This Row],[Costo Neto]]*0.19,0) -> 0 | H31: =Materias_Primas[[#This Row],[Costo Neto]]+Materias_Primas[[#This Row],[IVA Cred]] -> 0 | I31: {=MAX(IF(Compras!$F$11:$F$155='Materias Primas'!$A31,Compras!$M$11:$M$155,'Materias Primas'!$H31))} -> 0 | J31: =IFERROR(ROUND(I31/D31,0),"")
F32: 0 | G32: =ROUND(Materias_Primas[[#This Row],[Costo Neto]]*0.19,0) -> 0 | H32: =Materias_Primas[[#This Row],[Costo Neto]]+Materias_Primas[[#This Row],[IVA Cred]] -> 0 | I32: {=MAX(IF(Compras!$F$11:$F$155='Materias Primas'!$A32,Compras!$M$11:$M$155,'Materias Primas'!$H32))} -> 0 | J32: =IFERROR(ROUND(I32/D32,0),"")
F33: 0 | G33: =ROUND(Materias_Primas[[#This Row],[Costo Neto]]*0.19,0) -> 0 | H33: =Materias_Primas[[#This Row],[Costo Neto]]+Materias_Primas[[#This Row],[IVA Cred]] -> 0 | I33: {=MAX(IF(Compras!$F$11:$F$155='Materias Primas'!$A33,Compras!$M$11:$M$155,'Materias Primas'!$H33))} -> 0 | J33: =IFERROR(ROUND(I33/D33,0),"")
F34: 0 | G34: =ROUND(Materias_Primas[[#This Row],[Costo Neto]]*0.19,0) -> 0 | H34: =Materias_Primas[[#This Row],[Costo Neto]]+Materias_Primas[[#This Row],[IVA Cred]] -> 0 | I34: {=MAX(IF(Compras!$F$11:$F$155='Materias Primas'!$A34,Compras!$M$11:$M$155,'Materias Primas'!$H34))} -> 0 | J34: =IFERROR(ROUND(I34/D34,0),"")
F35: 0 | G35: =ROUND(Materias_Primas[[#This Row],[Costo Neto]]*0.19,0) -> 0 | H35: =Materias_Primas[[#This Row],[Costo Neto]]+Materias_Primas[[#This Row],[IVA Cred]] -> 0 | I35: {=MAX(IF(Compras!$F$11:$F$155='Materias Primas'!$A35,Compras!$M$11:$M$155,'Materias Primas'!$H35))} -> 0 | J35: =IFERROR(ROUND(I35/D35,0),"")
F36: 0 | G36: =ROUND(Materias_Primas[[#This Row],[Costo Neto]]*0.19,0) -> 0 | H36: =Materias_Primas[[#This Row],[Costo Neto]]+Materias_Primas[[#This Row],[IVA Cred]] -> 0 | I36: {=MAX(IF(Compras!$F$11:$F$155='Materias Primas'!$A36,Compras!$M$11:$M$155,'Materias Primas'!$H36))} -> 0 | J36: =IFERROR(ROUND(I36/D36,0),"")
F37: 0 | G37: =ROUND(Materias_Primas[[#This Row],[Costo Neto]]*0.19,0) -> 0 | H37: =Materias_Primas[[#This Row],[Costo Neto]]+Materias_Primas[[#This Row],[IVA Cred]] -> 0 | I37: {=MAX(IF(Compras!$F$11:$F$155='Materias Primas'!$A37,Compras!$M$11:$M$155,'Materias Primas'!$H37))} -> 0 | J37: =IFERROR(ROUND(I37/D37,0),"")
F38: 0 | G38: =ROUND(Materias_Primas[[#This Row],[Costo Neto]]*0.19,0) -> 0 | H38: =Materias_Primas[[#This Row],[Costo Neto]]+Materias_Primas[[#This Row],[IVA Cred]] -> 0 | I38: {=MAX(IF(Compras!$F$11:$F$155='Materias Primas'!$A38,Compras!$M$11:$M$155,'Materias Primas'!$H38))} -> 0 | J38: =IFERROR(ROUND(I38/D38,0),"")
F39: 0 | G39: =ROUND(Materias_Primas[[#This Row],[Costo Neto]]*0.19,0) -> 0 | H39: =Materias_Primas[[#This Row],[Costo Neto]]+Materias_Primas[[#This Row],[IVA Cred]] -> 0 | I39: {=MAX(IF(Compras!$F$11:$F$155='Materias Primas'!$A39,Compras!$M$11:$M$155,'Materias Primas'!$H39))} -> 0 | J39: =IFERROR(ROUND(I39/D39,0),"")
F40: 0 | G40: =ROUND(Materias_Primas[[#This Row],[Costo Neto]]*0.19,0) -> 0 | H40: =Materias_Primas[[#This Row],[Costo Neto]]+Materias_Primas[[#This Row],[IVA Cred]] -> 0 | I40: {=MAX(IF(Compras!$F$11:$F$155='Materias Primas'!$A40,Compras!$M$11:$M$155,'Materias Primas'!$H40))} -> 0 | J40: =IFERROR(ROUND(I40/D40,0),"")
A41: GA-01 | B41: Locomoción | D41: 1 | E41: Uni | F41: 840 | G41: =ROUND(Materias_Primas[[#This Row],[Costo Neto]]*0.19,0) -> 160 | H41: =Materias_Primas[[#This Row],[Costo Neto]]+Materias_Primas[[#This Row],[IVA Cred]] -> 1000 | I41: {=MAX(IF(Compras!$F$11:$F$155='Materias Primas'!$A41,Compras!$M$11:$M$155,'Materias Primas'!$H41))} -> 1000 | J41: =IFERROR(ROUND(I41/D41,0),"") -> 1000
F42: 0 | G42: =ROUND(Materias_Primas[[#This Row],[Costo Neto]]*0.19,0) -> 0 | H42: =Materias_Primas[[#This Row],[Costo Neto]]+Materias_Primas[[#This Row],[IVA Cred]] -> 0 | I42: {=MAX(IF(Compras!$F$11:$F$155='Materias Primas'!$A42,Compras!$M$11:$M$155,'Materias Primas'!$H42))} -> 0 | J42: =IFERROR(ROUND(I42/D42,0),"")
F43: 0 | G43: =ROUND(Materias_Primas[[#This Row],[Costo Neto]]*0.19,0) -> 0 | H43: =Materias_Primas[[#This Row],[Costo Neto]]+Materias_Primas[[#This Row],[IVA Cred]] -> 0 | I43: {=MAX(IF(Compras!$F$11:$F$155='Materias Primas'!$A43,Compras!$M$11:$M$155,'Materias Primas'!$H43))} -> 0 | J43: =IFERROR(ROUND(I43/D43,0),"")
A44: SE-01 | B44: DTF | D44: 1 | E44: Cm2 | F44: 30 | G44: =ROUND(Materias_Primas[[#This Row],[Costo Neto]]*0.19,0) -> 6 | H44: =Materias_Primas[[#This Row],[Costo Neto]]+Materias_Primas[[#This Row],[IVA Cred]] -> 36 | I44: {=MAX(IF(Compras!$F$11:$F$155='Materias Primas'!$A44,Compras!$M$11:$M$155,'Materias Primas'!$H44))} -> 36 | J44: =IFERROR(ROUND(I44/D44,0),"") -> 36
F45: 0 | G45: =ROUND(Materias_Primas[[#This Row],[Costo Neto]]*0.19,0) -> 0 | H45: =Materias_Primas[[#This Row],[Costo Neto]]+Materias_Primas[[#This Row],[IVA Cred]] -> 0 | I45: {=MAX(IF(Compras!$F$11:$F$155='Materias Primas'!$A45,Compras!$M$11:$M$155,'Materias Primas'!$H45))} -> 0 | J45: =IFERROR(ROUND(I45/D45,0),"")
F46: 0 | G46: =ROUND(Materias_Primas[[#This Row],[Costo Neto]]*0.19,0) -> 0 | H46: =Materias_Primas[[#This Row],[Costo Neto]]+Materias_Primas[[#This Row],[IVA Cred]] -> 0 | I46: {=MAX(IF(Compras!$F$11:$F$155='Materias Primas'!$A46,Compras!$M$11:$M$155,'Materias Primas'!$H46))} -> 0 | J46: =IFERROR(ROUND(I46/D46,0),"")
F47: 0 | G47: =ROUND(Materias_Primas[[#This Row],[Costo Neto]]*0.19,0) -> 0 | H47: =Materias_Primas[[#This Row],[Costo Neto]]+Materias_Primas[[#This Row],[IVA Cred]] -> 0 | I47: {=MAX(IF(Compras!$F$11:$F$155='Materias Primas'!$A47,Compras!$M$11:$M$155,'Materias Primas'!$H47))} -> 0 | J47: =IFERROR(ROUND(I47/D47,0),"")
F48: 0 | G48: =ROUND(Materias_Primas[[#This Row],[Costo Neto]]*0.19,0) -> 0 | H48: =Materias_Primas[[#This Row],[Costo Neto]]+Materias_Primas[[#This Row],[IVA Cred]] -> 0 | I48: {=MAX(IF(Compras!$F$11:$F$155='Materias Primas'!$A48,Compras!$M$11:$M$155,'Materias Primas'!$H48))} -> 0 | J48: =IFERROR(ROUND(I48/D48,0),"")
F49: 0 | G49: =ROUND(Materias_Primas[[#This Row],[Costo Neto]]*0.19,0) -> 0 | H49: =Materias_Primas[[#This Row],[Costo Neto]]+Materias_Primas[[#This Row],[IVA Cred]] -> 0 | I49: {=MAX(IF(Compras!$F$11:$F$155='Materias Primas'!$A49,Compras!$M$11:$M$155,'Materias Primas'!$H49))} -> 0 | J49: =IFERROR(ROUND(I49/D49,0),"")
F50: 0 | G50: =ROUND(Materias_Primas[[#This Row],[Costo Neto]]*0.19,0) -> 0 | H50: =Materias_Primas[[#This Row],[Costo Neto]]+Materias_Primas[[#This Row],[IVA Cred]] -> 0 | I50: {=MAX(IF(Compras!$F$11:$F$155='Materias Primas'!$A50,Compras!$M$11:$M$155,'Materias Primas'!$H50))} -> 0 | J50: =IFERROR(ROUND(I50/D50,0),"")
F51: 0 | G51: =ROUND(Materias_Primas[[#This Row],[Costo Neto]]*0.19,0) -> 0 | H51: =Materias_Primas[[#This Row],[Costo Neto]]+Materias_Primas[[#This Row],[IVA Cred]] -> 0 | I51: {=MAX(IF(Compras!$F$11:$F$155='Materias Primas'!$A51,Compras!$M$11:$M$155,'Materias Primas'!$H51))} -> 0 | J51: =IFERROR(ROUND(I51/D51,0),"")
F52: 0 | G52: =ROUND(Materias_Primas[[#This Row],[Costo Neto]]*0.19,0) -> 0 | H52: =Materias_Primas[[#This Row],[Costo Neto]]+Materias_Primas[[#This Row],[IVA Cred]] -> 0 | I52: {=MAX(IF(Compras!$F$11:$F$155='Materias Primas'!$A52,Compras!$M$11:$M$155,'Materias Primas'!$H52))} -> 0 | J52: =IFERROR(ROUND(I52/D52,0),"")
F53: 0 | G53: =ROUND(Materias_Primas[[#This Row],[Costo Neto]]*0.19,0) -> 0 | H53: =Materias_Primas[[#This Row],[Costo Neto]]+Materias_Primas[[#This Row],[IVA Cred]] -> 0 | I53: {=MAX(IF(Compras!$F$11:$F$155='Materias Primas'!$A53,Compras!$M$11:$M$155,'Materias Primas'!$H53))} -> 0 | J53: =IFERROR(ROUND(I53/D53,0),"")
F54: 0 | G54: =ROUND(Materias_Primas[[#This Row],[Costo Neto]]*0.19,0) -> 0 | H54: =Materias_Primas[[#This Row],[Costo Neto]]+Materias_Primas[[#This Row],[IVA Cred]] -> 0 | I54: {=MAX(IF(Compras!$F$11:$F$155='Materias Primas'!$A54,Compras!$M$11:$M$155,'Materias Primas'!$H54))} -> 0 | J54: =IFERROR(ROUND(I54/D54,0),"")
F55: 0 | G55: =ROUND(Materias_Primas[[#This Row],[Costo Neto]]*0.19,0) -> 0 | H55: =Materias_Primas[[#This Row],[Costo Neto]]+Materias_Primas[[#This Row],[IVA Cred]] -> 0 | I55: {=MAX(IF(Compras!$F$11:$F$155='Materias Primas'!$A55,Compras!$M$11:$M$155,'Materias Primas'!$H55))} -> 0 | J55: =IFERROR(ROUND(I55/D55,0),"")
...

Sheet Receta
A1: Código | B1: Nombre P | C1: Cant PR | D1: ÍTEM | E1: M P | F1: TIPO | G1: Nombre | H1: Cant MP | I1: Unid | J1: C R | K1: CU | L1: Tipo2
A2: TO-07 | B2: =IFERROR(VLOOKUP('Receta'!$A2,Productos[#All],2,0),"") -> Toalla 160x80 Na | C2: 1 | D2: 1 | E2: TE-01 | F2: =IFERROR(VLOOKUP(E2,Materias_Primas[#All],3,0),"") -> MP | G2: =IFERROR(VLOOKUP('Receta'!$E2,Materias_Primas[#All],2,0),"") -> Microfibra Dep 160 Na | H2: 0.8 | I2: =IFERROR(VLOOKUP('Receta'!$E2,Materias_Primas[#All],5,0),"") -> Mts | J2: =IFERROR(H2*VLOOKUP('Receta'!$E2,Materias_Primas[#All],10,0),"") -> 3920 | K2: =IFERROR('Receta'!$J2/'Receta'!$C2,"") -> 3920 | L2: =IFERROR(VLOOKUP('Receta'!$A2,Productos[#All],3,0),"") -> Toalla
A3: TO-07 | B3: =IFERROR(VLOOKUP('Receta'!$A3,Productos[#All],2,0),"") -> Toalla 160x80 Na | C3: 1 | D3: 2 | E3: HI-01 | F3: =IFERROR(VLOOKUP(E3,Materias_Primas[#All],3,0),"") -> IN | G3: =IFERROR(VLOOKUP('Receta'!$E3,Materias_Primas[#All],2,0),"") -> Hilo Overlock Verde | H3: =1/25 -> 0.04 | I3: =IFERROR(VLOOKUP('Receta'!$E3,Materias_Primas[#All],5,0),"") -> Uni | J3: =IFERROR(H3*VLOOKUP('Receta'!$E3,Materias_Primas[#All],10,0),"") -> 51.96 | K3: =IFERROR('Receta'!$J3/'Receta'!$C3,"") -> 51.96 | L3: =IFERROR(VLOOKUP('Receta'!$A3,Productos[#All],3,0),"") -> Toalla
A4: TO-07 | B4: =IFERROR(VLOOKUP('Receta'!$A4,Productos[#All],2,0),"") -> Toalla 160x80 Na | C4: 1 | D4: 3 | E4: HI-02 | F4: =IFERROR(VLOOKUP(E4,Materias_Primas[#All],3,0),"") -> IN | G4: =IFERROR(VLOOKUP('Receta'!$E4,Materias_Primas[#All],2,0),"") -> Hilo Recta Verde | H4: 0.04 | I4: =IFERROR(VLOOKUP('Receta'!$E4,Materias_Primas[#All],5,0),"") -> Uni | J4: =IFERROR(H4*VLOOKUP('Receta'!$E4,Materias_Primas[#All],10,0),"") -> 35.6 | K4: =IFERROR('Receta'!$J4/'Receta'!$C4,"") -> 35.6 | L4: =IFERROR(VLOOKUP('Receta'!$A4,Productos[#All],3,0),"") -> Toalla
A5: TO-07 | B5: =IFERROR(VLOOKUP('Receta'!$A5,Productos[#All],2,0),"") -> Toalla 160x80 Na | C5: 1 | D5: 4 | E5: GA-01 | F5: =IFERROR(VLOOKUP(E5,Materias_Primas[#All],3,0),"") -> 0 | G5: =IFERROR(VLOOKUP('Receta'!$E5,Materias_Primas[#All],2,0),"") -> Locomoción | H5: 0.1 | I5: =IFERROR(VLOOKUP('Receta'!$E5,Materias_Primas[#All],5,0),"") -> Uni | J5: =IFERROR(H5*VLOOKUP('Receta'!$E5,Materias_Primas[#All],10,0),"") -> 100 | K5: =IFERROR('Receta'!$J5/'Receta'!$C5,"") -> 100 | L5: =IFERROR(VLOOKUP('Receta'!$A5,Productos[#All],3,0),"") -> Toalla
A6: TO-06 | B6: =IFERROR(VLOOKUP('Receta'!$A6,Productos[#All],2,0),"") -> Toalla 160x80 Fu | C6: 1 | D6: 1 | E6: TE-03 | F6: =IFERROR(VLOOKUP(E6,Materias_Primas[#All],3,0),"") -> MP | G6: =IFERROR(VLOOKUP('Receta'!$E6,Materias_Primas[#All],2,0),"") -> Microfibra Dep 160 Fu | H6: 0.8 | I6: =IFERROR(VLOOKUP('Receta'!$E6,Materias_Primas[#All],5,0),"") -> Mts | J6: =IFERROR(H6*VLOOKUP('Receta'!$E6,Materias_Primas[#All],10,0),"") -> 3920 | K6: =IFERROR('Receta'!$J6/'Receta'!$C6,"") -> 3920 | L6: =IFERROR(VLOOKUP('Receta'!$A6,Productos[#All],3,0),"") -> Toalla
A7: TO-06 | B7: =IFERROR(VLOOKUP('Receta'!$A7,Productos[#All],2,0),"") -> Toalla 160x80 Fu | C7: 1 | D7: 2 | E7: HI-01 | F7: =IFERROR(VLOOKUP(E7,Materias_Primas[#All],3,0),"") -> IN | G7: =IFERROR(VLOOKUP('Receta'!$E7,Materias_Primas[#All],2,0),"") -> Hilo Overlock Verde | H7: =1/25 -> 0.04 | I7: =IFERROR(VLOOKUP('Receta'!$E7,Materias_Primas[#All],5,0),"") -> Uni | J7: =IFERROR(H7*VLOOKUP('Receta'!$E7,Materias_Primas[#All],10,0),"") -> 51.96 | K7: =IFERROR('Receta'!$J7/'Receta'!$C7,"") -> 51.96 | L7: =IFERROR(VLOOKUP('Receta'!$A7,Productos[#All],3,0),"") -> Toalla
A8: TO-06 | B8: =IFERROR(VLOOKUP('Receta'!$A8,Productos[#All],2,0),"") -> Toalla 160x80 Fu | C8: 1 | D8: 3 | E8: HI-02 | F8: =IFERROR(VLOOKUP(E8,Materias_Primas[#All],3,0),"") -> IN | G8: =IFERROR(VLOOKUP('Receta'!$E8,Materias_Primas[#All],2,0),"") -> Hilo Recta Verde | H8: 0.04 | I8: =IFERROR(VLOOKUP('Receta'!$E8,Materias_Primas[#All],5,0),"") -> Uni | J8: =IFERROR(H8*VLOOKUP('Receta'!$E8,Materias_Primas[#All],10,0),"") -> 35.6 | K8: =IFERROR('Receta'!$J8/'Receta'!$C8,"") -> 35.6 | L8: =IFERROR(VLOOKUP('Receta'!$A8,Productos[#All],3,0),"") -> Toalla
A9: TO-06 | B9: =IFERROR(VLOOKUP('Receta'!$A9,Productos[#All],2,0),"") -> Toalla 160x80 Fu | C9: 1 | D9: 4 | E9: GA-01 | F9: =IFERROR(VLOOKUP(E9,Materias_Primas[#All],3,0),"") -> 0 | G9: =IFERROR(VLOOKUP('Receta'!$E9,Materias_Primas[#All],2,0),"") -> Locomoción | H9: 0.1 | I9: =IFERROR(VLOOKUP('Receta'!$E9,Materias_Primas[#All],5,0),"") -> Uni | J9: =IFERROR(H9*VLOOKUP('Receta'!$E9,Materias_Primas[#All],10,0),"") -> 100 | K9: =IFERROR('Receta'!$J9/'Receta'!$C9,"") -> 100 | L9: =IFERROR(VLOOKUP('Receta'!$A9,Productos[#All],3,0),"") -> Toalla
A10: TO-01 | B10: =IFERROR(VLOOKUP('Receta'!$A10,Productos[#All],2,0),"") -> Toalla 160x80 Az | C10: 1 | D10: 1 | E10: TE-09 | F10: =IFERROR(VLOOKUP(E10,Materias_Primas[#All],3,0),"") -> MP | G10: =IFERROR(VLOOKUP('Receta'!$E10,Materias_Primas[#All],2,0),"") -> Microfibra Dep 160 Az | H10: 0.8 | I10: =IFERROR(VLOOKUP('Receta'!$E10,Materias_Primas[#All],5,0),"") -> Mts | J10: =IFERROR(H10*VLOOKUP('Receta'!$E10,Materias_Primas[#All],10,0),"") -> 3920 | K10: =IFERROR('Receta'!$J10/'Receta'!$C10,"") -> 3920 | L10: =IFERROR(VLOOKUP('Receta'!$A10,Productos[#All],3,0),"") -> Toalla
A11: TO-01 | B11: =IFERROR(VLOOKUP('Receta'!$A11,Productos[#All],2,0),"") -> Toalla 160x80 Az | C11: 1 | D11: 2 | E11: HI-01 | F11: =IFERROR(VLOOKUP(E11,Materias_Primas[#All],3,0),"") -> IN | G11: =IFERROR(VLOOKUP('Receta'!$E11,Materias_Primas[#All],2,0),"") -> Hilo Overlock Verde | H11: =1/25 -> 0.04 | I11: =IFERROR(VLOOKUP('Receta'!$E11,Materias_Primas[#All],5,0),"") -> Uni | J11: =IFERROR(H11*VLOOKUP('Receta'!$E11,Materias_Primas[#All],10,0),"") -> 51.96 | K11: =IFERROR('Receta'!$J11/'Receta'!$C11,"") -> 51.96 | L11: =IFERROR(VLOOKUP('Receta'!$A11,Productos[#All],3,0),"") -> Toalla
A12: TO-01 | B12: =IFERROR(VLOOKUP('Receta'!$A12,Productos[#All],2,0),"") -> Toalla 160x80 Az | C12: 1 | D12: 3 | E12: HI-02 | F12: =IFERROR(VLOOKUP(E12,Materias_Primas[#All],3,0),"") -> IN | G12: =IFERROR(VLOOKUP('Receta'!$E12,Materias_Primas[#All],2,0),"") -> Hilo Recta Verde | H12: 0.04 | I12: =IFERROR(VLOOKUP('Receta'!$E12,Materias_Primas[#All],5,0),"") -> Uni | J12: =IFERROR(H12*VLOOKUP('Receta'!$E12,Materias_Primas[#All],10,0),"") -> 35.6 | K12: =IFERROR('Receta'!$J12/'Receta'!$C12,"") -> 35.6 | L12: =IFERROR(VLOOKUP('Receta'!$A12,Productos[#All],3,0),"") -> Toalla
A13: TO-01 | B13: =IFERROR(VLOOKUP('Receta'!$A13,Productos[#All],2,0),"") -> Toalla 160x80 Az | C13: 1 | D13: 4 | E13: GA-01 | F13: =IFERROR(VLOOKUP(E13,Materias_Primas[#All],3,0),"") -> 0 | G13: =IFERROR(VLOOKUP('Receta'!$E13,Materias_Primas[#All],2,0),"") -> Locomoción | H13: 0.1 | I13: =IFERROR(VLOOKUP('Receta'!$E13,Materias_Primas[#All],5,0),"") -> Uni | J13: =IFERROR(H13*VLOOKUP('Receta'!$E13,Materias_Primas[#All],10,0),"") -> 100 | K13: =IFERROR('Receta'!$J13/'Receta'!$C13,"") -> 100 | L13: =IFERROR(VLOOKUP('Receta'!$A13,Productos[#All],3,0),"") -> Toalla
A14: TO-02 | B14: =IFERROR(VLOOKUP('Receta'!$A14,Productos[#All],2,0),"") -> Toalla 160x80 Ro | C14: 1 | D14: 1 | E14: TE-07 | F14: =IFERROR(VLOOKUP(E14,Materias_Primas[#All],3,0),"") -> MP | G14: =IFERROR(VLOOKUP('Receta'!$E14,Materias_Primas[#All],2,0),"") -> Microfibra Dep 160 Ro | H14: 0.8 | I14: =IFERROR(VLOOKUP('Receta'!$E14,Materias_Primas[#All],5,0),"") -> Mts | J14: =IFERROR(H14*VLOOKUP('Receta'!$E14,Materias_Primas[#All],10,0),"") -> 3920 | K14: =IFERROR('Receta'!$J14/'Receta'!$C14,"") -> 3920 | L14: =IFERROR(VLOOKUP('Receta'!$A14,Productos[#All],3,0),"") -> Toalla
A15: TO-02 | B15: =IFERROR(VLOOKUP('Receta'!$A15,Productos[#All],2,0),"") -> Toalla 160x80 Ro | C15: 1 | D15: 2 | E15: HI-01 | F15: =IFERROR(VLOOKUP(E15,Materias_Primas[#All],3,0),"") -> IN | G15: =IFERROR(VLOOKUP('Receta'!$E15,Materias_Primas[#All],2,0),"") -> Hilo Overlock Verde | H15: =1/25 -> 0.04 | I15: =IFERROR(VLOOKUP('Receta'!$E15,Materias_Primas[#All],5,0),"") -> Uni | J15: =IFERROR(H15*VLOOKUP('Receta'!$E15,Materias_Primas[#All],10,0),"") -> 51.96 | K15: =IFERROR('Receta'!$J15/'Receta'!$C15,"") -> 51.96 | L15: =IFERROR(VLOOKUP('Receta'!$A15,Productos[#All],3,0),"") -> Toalla
A16: TO-02 | B16: =IFERROR(VLOOKUP('Receta'!$A16,Productos[#All],2,0),"") -> Toalla 160x80 Ro | C16: 1 | D16: 3 | E16: HI-02 | F16: =IFERROR(VLOOKUP(E16,Materias_Primas[#All],3,0),"") -> IN | G16: =IFERROR(VLOOKUP('Receta'!$E16,Materias_Primas[#All],2,0),"") -> Hilo Recta Verde | H16: 0.04 | I16: =IFERROR(VLOOKUP('Receta'!$E16,Materias_Primas[#All],5,0),"") -> Uni | J16: =IFERROR(H16*VLOOKUP('Receta'!$E16,Materias_Primas[#All],10,0),"") -> 35.6 | K16: =IFERROR('Receta'!$J16/'Receta'!$C16,"") -> 35.6 | L16: =IFERROR(VLOOKUP('Receta'!$A16,Productos[#All],3,0),"") -> Toalla
A17: TO-02 | B17: =IFERROR(VLOOKUP('Receta'!$A17,Productos[#All],2,0),"") -> Toalla 160x80 Ro | C17: 1 | D17: 4 | E17: GA-01 | F17: =IFERROR(VLOOKUP(E17,Materias_Primas[#All],3,0),"") -> 0 | G17: =IFERROR(VLOOKUP('Receta'!$E17,Materias_Primas[#All],2,0),"") -> Locomoción | H17: 0.1 | I17: =IFERROR(VLOOKUP('Receta'!$E17,Materias_Primas[#All],5,0),"") -> Uni | J17: =IFERROR(H17*VLOOKUP('Receta'!$E17,Materias_Primas[#All],10,0),"") -> 100 | K17: =IFERROR('Receta'!$J17/'Receta'!$C17,"") -> 100 | L17: =IFERROR(VLOOKUP('Receta'!$A17,Productos[#All],3,0),"") -> Toalla
A18: TO-04 | B18: =IFERROR(VLOOKUP('Receta'!$A18,Productos[#All],2,0),"") -> Toalla 160x80 Vp | C18: 1 | D18: 1 | E18: TE-08 | F18: =IFERROR(VLOOKUP(E18,Materias_Primas[#All],3,0),"") -> MP | G18: =IFERROR(VLOOKUP('Receta'!$E18,Materias_Primas[#All],2,0),"") -> Microfibra Dep 160 Vp | H18: 0.8 | I18: =IFERROR(VLOOKUP('Receta'!$E18,Materias_Primas[#All],5,0),"") -> Mts | J18: =IFERROR(H18*VLOOKUP('Receta'!$E18,Materias_Primas[#All],10,0),"") -> 3920 | K18: =IFERROR('Receta'!$J18/'Receta'!$C18,"") -> 3920 | L18: =IFERROR(VLOOKUP('Receta'!$A18,Productos[#All],3,0),"") -> Toalla
A19: TO-04 | B19: =IFERROR(VLOOKUP('Receta'!$A19,Productos[#All],2,0),"") -> Toalla 160x80 Vp | C19: 1 | D19: 2 | E19: HI-01 | F19: =IFERROR(VLOOKUP(E19,Materias_Primas[#All],3,0),"") -> IN | G19: =IFERROR(VLOOKUP('Receta'!$E19,Materias_Primas[#All],2,0),"") -> Hilo Overlock Verde | H19: =1/25 -> 0.04 | I19: =IFERROR(VLOOKUP('Receta'!$E19,Materias_Primas[#All],5,0),"") -> Uni | J19: =IFERROR(H19*VLOOKUP('Receta'!$E19,Materias_Primas[#All],10,0),"") -> 51.96 | K19: =IFERROR('Receta'!$J19/'Receta'!$C19,"") -> 51.96 | L19: =IFERROR(VLOOKUP('Receta'!$A19,Productos[#All],3,0),"") -> Toalla
A20: TO-04 | B20: =IFERROR(VLOOKUP('Receta'!$A20,Productos[#All],2,0),"") -> Toalla 160x80 Vp | C20: 1 | D20: 3 | E20: HI-02 | F20: =IFERROR(VLOOKUP(E20,Materias_Primas[#All],3,0),"") -> IN | G20: =IFERROR(VLOOKUP('Receta'!$E20,Materias_Primas[#All],2,0),"") -> Hilo Recta Verde | H20: 0.04 | I20: =IFERROR(VLOOKUP('Receta'!$E20,Materias_Primas[#All],5,0),"") -> Uni | J20: =IFERROR(H20*VLOOKUP('Receta'!$E20,Materias_Primas[#All],10,0),"") -> 35.6 | K20: =IFERROR('Receta'!$J20/'Receta'!$C20,"") -> 35.6 | L20: =IFERROR(VLOOKUP('Receta'!$A20,Productos[#All],3,0),"") -> Toalla
A21: TO-04 | B21: =IFERROR(VLOOKUP('Receta'!$A21,Productos[#All],2,0),"") -> Toalla 160x80 Vp | C21: 1 | D21: 4 | E21: GA-01 | F21: =IFERROR(VLOOKUP(E21,Materias_Primas[#All],3,0),"") -> 0 | G21: =IFERROR(VLOOKUP('Receta'!$E21,Materias_Primas[#All],2,0),"") -> Locomoción | H21: 0.1 | I21: =IFERROR(VLOOKUP('Receta'!$E21,Materias_Primas[#All],5,0),"") -> Uni | J21: =IFERROR(H21*VLOOKUP('Receta'!$E21,Materias_Primas[#All],10,0),"") -> 100 | K21: =IFERROR('Receta'!$J21/'Receta'!$C21,"") -> 100 | L21: =IFERROR(VLOOKUP('Receta'!$A21,Productos[#All],3,0),"") -> Toalla
A22: TO-05 | B22: =IFERROR(VLOOKUP('Receta'!$A22,Productos[#All],2,0),"") -> Toalla 160x80 Ca | C22: 1 | D22: 1 | E22: TE-04 | F22: =IFERROR(VLOOKUP(E22,Materias_Primas[#All],3,0),"") -> MP | G22: =IFERROR(VLOOKUP('Receta'!$E22,Materias_Primas[#All],2,0),"") -> Microfibra Dep 160 Ca | H22: 0.8 | I22: =IFERROR(VLOOKUP('Receta'!$E22,Materias_Primas[#All],5,0),"") -> Mts | J22: =IFERROR(H22*VLOOKUP('Receta'!$E22,Materias_Primas[#All],10,0),"") -> 3920 | K22: =IFERROR('Receta'!$J22/'Receta'!$C22,"") -> 3920 | L22: =IFERROR(VLOOKUP('Receta'!$A22,Productos[#All],3,0),"") -> Toalla
A23: TO-05 | B23: =IFERROR(VLOOKUP('Receta'!$A23,Productos[#All],2,0),"") -> Toalla 160x80 Ca | C23: 1 | D23: 2 | E23: HI-01 | F23: =IFERROR(VLOOKUP(E23,Materias_Primas[#All],3,0),"") -> IN | G23: =IFERROR(VLOOKUP('Receta'!$E23,Materias_Primas[#All],2,0),"") -> Hilo Overlock Verde | H23: =1/25 -> 0.04 | I23: =IFERROR(VLOOKUP('Receta'!$E23,Materias_Primas[#All],5,0),"") -> Uni | J23: =IFERROR(H23*VLOOKUP('Receta'!$E23,Materias_Primas[#All],10,0),"") -> 51.96 | K23: =IFERROR('Receta'!$J23/'Receta'!$C23,"") -> 51.96 | L23: =IFERROR(VLOOKUP('Receta'!$A23,Productos[#All],3,0),"") -> Toalla
A24: TO-05 | B24: =IFERROR(VLOOKUP('Receta'!$A24,Productos[#All],2,0),"") -> Toalla 160x80 Ca | C24: 1 | D24: 3 | E24: HI-02 | F24: =IFERROR(VLOOKUP(E24,Materias_Primas[#All],3,0),"") -> IN | G24: =IFERROR(VLOOKUP('Receta'!$E24,Materias_Primas[#All],2,0),"") -> Hilo Recta Verde | H24: 0.04 | I24: =IFERROR(VLOOKUP('Receta'!$E24,Materias_Primas[#All],5,0),"") -> Uni | J24: =IFERROR(H24*VLOOKUP('Receta'!$E24,Materias_Primas[#All],10,0),"") -> 35.6 | K24: =IFERROR('Receta'!$J24/'Receta'!$C24,"") -> 35.6 | L24: =IFERROR(VLOOKUP('Receta'!$A24,Productos[#All],3,0),"") -> Toalla
A25: TO-05 | B25: =IFERROR(VLOOKUP('Receta'!$A25,Productos[#All],2,0),"") -> Toalla 160x80 Ca | C25: 1 | D25: 4 | E25: GA-01 | F25: =IFERROR(VLOOKUP(E25,Materias_Primas[#All],3,0),"") -> 0 | G25: =IFERROR(VLOOKUP('Receta'!$E25,Materias_Primas[#All],2,0),"") -> Locomoción | H25: 0.1 | I25: =IFERROR(VLOOKUP('Receta'!$E25,Materias_Primas[#All],5,0),"") -> Uni | J25: =IFERROR(H25*VLOOKUP('Receta'!$E25,Materias_Primas[#All],10,0),"") -> 100 | K25: =IFERROR('Receta'!$J25/'Receta'!$C25,"") -> 100 | L25: =IFERROR(VLOOKUP('Receta'!$A25,Productos[#All],3,0),"") -> Toalla
A26: TO-08 | B26: =IFERROR(VLOOKUP('Receta'!$A26,Productos[#All],2,0),"") -> Toalla 160x80 Ne | C26: 1 | D26: 1 | E26: TE-05 | F26: =IFERROR(VLOOKUP(E26,Materias_Primas[#All],3,0),"") -> MP | G26: =IFERROR(VLOOKUP('Receta'!$E26,Materias_Primas[#All],2,0),"") -> Microfibra Dep 160 Ne | H26: 0.8 | I26: =IFERROR(VLOOKUP('Receta'!$E26,Materias_Primas[#All],5,0),"") -> Mts | J26: =IFERROR(H26*VLOOKUP('Receta'!$E26,Materias_Primas[#All],10,0),"") -> 3920 | K26: =IFERROR('Receta'!$J26/'Receta'!$C26,"") -> 3920 | L26: =IFERROR(VLOOKUP('Receta'!$A26,Productos[#All],3,0),"") -> Toalla
A27: TO-08 | B27: =IFERROR(VLOOKUP('Receta'!$A27,Productos[#All],2,0),"") -> Toalla 160x80 Ne | C27: 1 | D27: 2 | E27: HI-01 | F27: =IFERROR(VLOOKUP(E27,Materias_Primas[#All],3,0),"") -> IN | G27: =IFERROR(VLOOKUP('Receta'!$E27,Materias_Primas[#All],2,0),"") -> Hilo Overlock Verde | H27: =1/25 -> 0.04 | I27: =IFERROR(VLOOKUP('Receta'!$E27,Materias_Primas[#All],5,0),"") -> Uni | J27: =IFERROR(H27*VLOOKUP('Receta'!$E27,Materias_Primas[#All],10,0),"") -> 51.96 | K27: =IFERROR('Receta'!$J27/'Receta'!$C27,"") -> 51.96 | L27: =IFERROR(VLOOKUP('Receta'!$A27,Productos[#All],3,0),"") -> Toalla
A28: TO-08 | B28: =IFERROR(VLOOKUP('Receta'!$A28,Productos[#All],2,0),"") -> Toalla 160x80 Ne | C28: 1 | D28: 3 | E28: HI-02 | F28: =IFERROR(VLOOKUP(E28,Materias_Primas[#All],3,0),"") -> IN | G28: =IFERROR(VLOOKUP('Receta'!$E28,Materias_Primas[#All],2,0),"") -> Hilo Recta Verde | H28: 0.04 | I28: =IFERROR(VLOOKUP('Receta'!$E28,Materias_Primas[#All],5,0),"") -> Uni | J28: =IFERROR(H28*VLOOKUP('Receta'!$E28,Materias_Primas[#All],10,0),"") -> 35.6 | K28: =IFERROR('Receta'!$J28/'Receta'!$C28,"") -> 35.6 | L28: =IFERROR(VLOOKUP('Receta'!$A28,Productos[#All],3,0),"") -> Toalla
A29: TO-08 | B29: =IFERROR(VLOOKUP('Receta'!$A29,Productos[#All],2,0),"") -> Toalla 160x80 Ne | C29: 1 | D29: 4 | E29: GA-01 | F29: =IFERROR(VLOOKUP(E29,Materias_Primas[#All],3,0),"") -> 0 | G29: =IFERROR(VLOOKUP('Receta'!$E29,Materias_Primas[#All],2,0),"") -> Locomoción | H29: 0.1 | I29: =IFERROR(VLOOKUP('Receta'!$E29,Materias_Primas[#All],5,0),"") -> Uni | J29: =IFERROR(H29*VLOOKUP('Receta'!$E29,Materias_Primas[#All],10,0),"") -> 100 | K29: =IFERROR('Receta'!$J29/'Receta'!$C29,"") -> 100 | L29: =IFERROR(VLOOKUP('Receta'!$A29,Productos[#All],3,0),"") -> Toalla
A30: TO-09 | B30: =IFERROR(VLOOKUP('Receta'!$A30,Productos[#All],2,0),"") -> Toalla 80x40 Na | C30: 1 | D30: 1 | E30: TE-01 | F30: =IFERROR(VLOOKUP(E30,Materias_Primas[#All],3,0),"") -> MP | G30: =IFERROR(VLOOKUP('Receta'!$E30,Materias_Primas[#All],2,0),"") -> Microfibra Dep 160 Na | H30: 0.2 | I30: =IFERROR(VLOOKUP('Receta'!$E30,Materias_Primas[#All],5,0),"") -> Mts | J30: =IFERROR(H30*VLOOKUP('Receta'!$E30,Materias_Primas[#All],10,0),"") -> 980 | K30: =IFERROR('Receta'!$J30/'Receta'!$C30,"") -> 980 | L30: =IFERROR(VLOOKUP('Receta'!$A30,Productos[#All],3,0),"") -> Toalla
A31: TO-09 | B31: =IFERROR(VLOOKUP('Receta'!$A31,Productos[#All],2,0),"") -> Toalla 80x40 Na | C31: 1 | D31: 2 | E31: HI-01 | F31: =IFERROR(VLOOKUP(E31,Materias_Primas[#All],3,0),"") -> IN | G31: =IFERROR(VLOOKUP('Receta'!$E31,Materias_Primas[#All],2,0),"") -> Hilo Overlock Verde | H31: =1/100 -> 0.01 | I31: =IFERROR(VLOOKUP('Receta'!$E31,Materias_Primas[#All],5,0),"") -> Uni | J31: =IFERROR(H31*VLOOKUP('Receta'!$E31,Materias_Primas[#All],10,0),"") -> 12.99 | K31: =IFERROR('Receta'!$J31/'Receta'!$C31,"") -> 12.99 | L31: =IFERROR(VLOOKUP('Receta'!$A31,Productos[#All],3,0),"") -> Toalla
A32: TO-09 | B32: =IFERROR(VLOOKUP('Receta'!$A32,Productos[#All],2,0),"") -> Toalla 80x40 Na | C32: 1 | D32: 3 | E32: HI-02 | F32: =IFERROR(VLOOKUP(E32,Materias_Primas[#All],3,0),"") -> IN | G32: =IFERROR(VLOOKUP('Receta'!$E32,Materias_Primas[#All],2,0),"") -> Hilo Recta Verde | H32: 0.01 | I32: =IFERROR(VLOOKUP('Receta'!$E32,Materias_Primas[#All],5,0),"") -> Uni | J32: =IFERROR(H32*VLOOKUP('Receta'!$E32,Materias_Primas[#All],10,0),"") -> 8.9 | K32: =IFERROR('Receta'!$J32/'Receta'!$C32,"") -> 8.9 | L32: =IFERROR(VLOOKUP('Receta'!$A32,Productos[#All],3,0),"") -> Toalla
A33: TO-09 | B33: =IFERROR(VLOOKUP('Receta'!$A33,Productos[#All],2,0),"") -> Toalla 80x40 Na | C33: 1 | D33: 4 | E33: GA-01 | F33: =IFERROR(VLOOKUP(E33,Materias_Primas[#All],3,0),"") -> 0 | G33: =IFERROR(VLOOKUP('Receta'!$E33,Materias_Primas[#All],2,0),"") -> Locomoción | H33: 0.25 | I33: =IFERROR(VLOOKUP('Receta'!$E33,Materias_Primas[#All],5,0),"") -> Uni | J33: =IFERROR(H33*VLOOKUP('Receta'!$E33,Materias_Primas[#All],10,0),"") -> 250 | K33: =IFERROR('Receta'!$J33/'Receta'!$C33,"") -> 250 | L33: =IFERROR(VLOOKUP('Receta'!$A33,Productos[#All],3,0),"") -> Toalla
A34: TO-10 | B34: =IFERROR(VLOOKUP('Receta'!$A34,Productos[#All],2,0),"") -> Toalla 40x40 Na | C34: 1 | D34: 1 | E34: TE-01 | F34: =IFERROR(VLOOKUP(E34,Materias_Primas[#All],3,0),"") -> MP | G34: =IFERROR(VLOOKUP('Receta'!$E34,Materias_Primas[#All],2,0),"") -> Microfibra Dep 160 Na | H34: 0.1 | I34: =IFERROR(VLOOKUP('Receta'!$E34,Materias_Primas[#All],5,0),"") -> Mts | J34: =IFERROR(H34*VLOOKUP('Receta'!$E34,Materias_Primas[#All],10,0),"") -> 490 | K34: =IFERROR('Receta'!$J34/'Receta'!$C34,"") -> 490 | L34: =IFERROR(VLOOKUP('Receta'!$A34,Productos[#All],3,0),"") -> Toalla
A35: TO-10 | B35: =IFERROR(VLOOKUP('Receta'!$A35,Productos[#All],2,0),"") -> Toalla 40x40 Na | C35: 1 | D35: 2 | E35: HI-01 | F35: =IFERROR(VLOOKUP(E35,Materias_Primas[#All],3,0),"") -> IN | G35: =IFERROR(VLOOKUP('Receta'!$E35,Materias_Primas[#All],2,0),"") -> Hilo Overlock Verde | H35: 0.005 | I35: =IFERROR(VLOOKUP('Receta'!$E35,Materias_Primas[#All],5,0),"") -> Uni | J35: =IFERROR(H35*VLOOKUP('Receta'!$E35,Materias_Primas[#All],10,0),"") -> 6.495 | K35: =IFERROR('Receta'!$J35/'Receta'!$C35,"") -> 6.495 | L35: =IFERROR(VLOOKUP('Receta'!$A35,Productos[#All],3,0),"") -> Toalla
A36: TO-10 | B36: =IFERROR(VLOOKUP('Receta'!$A36,Productos[#All],2,0),"") -> Toalla 40x40 Na | C36: 1 | D36: 3 | E36: HI-02 | F36: =IFERROR(VLOOKUP(E36,Materias_Primas[#All],3,0),"") -> IN | G36: =IFERROR(VLOOKUP('Receta'!$E36,Materias_Primas[#All],2,0),"") -> Hilo Recta Verde | H36: 0.005 | I36: =IFERROR(VLOOKUP('Receta'!$E36,Materias_Primas[#All],5,0),"") -> Uni | J36: =IFERROR(H36*VLOOKUP('Receta'!$E36,Materias_Primas[#All],10,0),"") -> 4.45 | K36: =IFERROR('Receta'!$J36/'Receta'!$C36,"") -> 4.45 | L36: =IFERROR(VLOOKUP('Receta'!$A36,Productos[#All],3,0),"") -> Toalla
A37: TO-10 | B37: =IFERROR(VLOOKUP('Receta'!$A37,Productos[#All],2,0),"") -> Toalla 40x40 Na | C37: 1 | D37: 4 | E37: GA-01 | F37: =IFERROR(VLOOKUP(E37,Materias_Primas[#All],3,0),"") -> 0 | G37: =IFERROR(VLOOKUP('Receta'!$E37,Materias_Primas[#All],2,0),"") -> Locomoción | H37: 0.12 | I37: =IFERROR(VLOOKUP('Receta'!$E37,Materias_Primas[#All],5,0),"") -> Uni | J37: =IFERROR(H37*VLOOKUP('Receta'!$E37,Materias_Primas[#All],10,0),"") -> 120 | K37: =IFERROR('Receta'!$J37/'Receta'!$C37,"") -> 120 | L37: =IFERROR(VLOOKUP('Receta'!$A37,Productos[#All],3,0),"") -> Toalla
A38: TO-11 | B38: =IFERROR(VLOOKUP('Receta'!$A38,Productos[#All],2,0),"") -> Toalla 160x110 Na | C38: 1 | D38: 1 | E38: TE-01 | F38: =IFERROR(VLOOKUP(E38,Materias_Primas[#All],3,0),"") -> MP | G38: =IFERROR(VLOOKUP('Receta'!$E38,Materias_Primas[#All],2,0),"") -> Microfibra Dep 160 Na | H38: =0.8*1.5 -> 1.2 | I38: =IFERROR(VLOOKUP('Receta'!$E38,Materias_Primas[#All],5,0),"") -> Mts | J38: =IFERROR(H38*VLOOKUP('Receta'!$E38,Materias_Primas[#All],10,0),"") -> 5880 | K38: =IFERROR('Receta'!$J38/'Receta'!$C38,"") -> 5880 | L38: =IFERROR(VLOOKUP('Receta'!$A38,Productos[#All],3,0),"") -> Toalla
A39: TO-11 | B39: =IFERROR(VLOOKUP('Receta'!$A39,Productos[#All],2,0),"") -> Toalla 160x110 Na | C39: 1 | D39: 2 | E39: HI-01 | F39: =IFERROR(VLOOKUP(E39,Materias_Primas[#All],3,0),"") -> IN | G39: =IFERROR(VLOOKUP('Receta'!$E39,Materias_Primas[#All],2,0),"") -> Hilo Overlock Verde | H39: =1.5/25 -> 0.06 | I39: =IFERROR(VLOOKUP('Receta'!$E39,Materias_Primas[#All],5,0),"") -> Uni | J39: =IFERROR(H39*VLOOKUP('Receta'!$E39,Materias_Primas[#All],10,0),"") -> 77.94 | K39: =IFERROR('Receta'!$J39/'Receta'!$C39,"") -> 77.94 | L39: =IFERROR(VLOOKUP('Receta'!$A39,Productos[#All],3,0),"") -> Toalla
A40: TO-11 | B40: =IFERROR(VLOOKUP('Receta'!$A40,Productos[#All],2,0),"") -> Toalla 160x110 Na | C40: 1 | D40: 3 | E40: HI-02 | F40: =IFERROR(VLOOKUP(E40,Materias_Primas[#All],3,0),"") -> IN | G40: =IFERROR(VLOOKUP('Receta'!$E40,Materias_Primas[#All],2,0),"") -> Hilo Recta Verde | H40: 0.06 | I40: =IFERROR(VLOOKUP('Receta'!$E40,Materias_Primas[#All],5,0),"") -> Uni | J40: =IFERROR(H40*VLOOKUP('Receta'!$E40,Materias_Primas[#All],10,0),"") -> 53.4 | K40: =IFERROR('Receta'!$J40/'Receta'!$C40,"") -> 53.4 | L40: =IFERROR(VLOOKUP('Receta'!$A40,Productos[#All],3,0),"") -> Toalla
...

Sheet Proveedores
A1: Codigo | B1: Nombre | C1: Dirección | D1: Sector | E1: Teléfono | F1: Contacto | G1: WEB | H1: Observaciones
A2: 1 | B2: Pasajito Import. Calesa | C2: Pasajito mac clure | D2: Ind | E2: 56 997381561 | H2: Unico Tela MC Dep
A3: 2 | B3: Crayling vicuña M | C3: Av. Vicuña Mackenna 1415, Santiago | E3: 56 977935292 | F3: Sucursal | H3: Telas Bistrech y otras
A4: 3 | B4: Rainbown Publicidad | C4: Antonia Lopez de Bello 220, Recoleta | E4: 56 935179292 | F4: Johan Contreras , entrega 24 hrs. | H4: Sublimacion
A5: 4 | B5: Nahuel chile ltda | C5: Vargas buston 1088, San Miguel | E5: 56 966335702 | F5: Cobran por matriz, maximo 5 dias para entrega | G5: www.nahuelchileltda.cl | H5: Bordados
A6: 5 | B6: Textil Cassis S.A. | C6: Av. Jose Pedro Alessandri 1880, ñuñoa | E6: 56 982399670 | F6: Contacto: Raul | H6: Sublimacion por metros
A7: 6 | B7: Meriggi | C7: Av. Vicuña Mackenna 4525, san Joaquin | E7: 56 232734300 | G7: www.meriggi.cl | H7: Bistrech, Manteles Spandex, Granite
A8: 7 | B8: Calas | E8: 56 935646711 | G8: www.calas.cl | H8: Manteles Spandex, Mesas
A9: 8 | B9: Michel Neime | C9: Av Independencia 285. Independencia | E9: 22 735 2128 - 569 44502001 | H9: sesgo 1,5 $1210 20 mts
A10: 8 | B10: La muñequita | C10: Av. Independencia 381-383 | E10: 56 946926244 | H10: Telas granite y otras
A11: 9 | B11: Cristaleria La Paz | C11: Av. la Paz 126 | E11: 56 983017790 - 56 956532023 | H11: Cubiertos y menaje
A12: 10 | B12: Punto Chef | C12: Antonia Lopez de Bello 966. Independencia | E12: 56 976004569 | G12: www.puntochef.cl | H12: Cubiertos y menaje
A13: 11 | B13: Telas Pacifico
A14: 12
A15: 13
A16: 14

Sheet Ofertas
A1: S | B1: Proveedor | C1: Materia Prima | D1: Nombre | E1: Precio
A2: 2 | B2: =IFERROR(VLOOKUP(A2,Proveedores[#All],2,0),"") -> Crayling vicuña M | C2: TE-10 | D2: =IFERROR(VLOOKUP(C2,Materias_Primas[#All],2,0),"") -> Bistrech 150 cm Ne | E2: 780
A3: 2 | B3: =IFERROR(VLOOKUP(A3,Proveedores[#All],2,0),"") -> Crayling vicuña M | C3: TE-11 | D3: =IFERROR(VLOOKUP(C3,Materias_Primas[#All],2,0),"") -> Bistrech 300 cm Ne
A4: 2 | B4: =IFERROR(VLOOKUP(A4,Proveedores[#All],2,0),"") -> Crayling vicuña M | D4: =IFERROR(VLOOKUP(C4,Materias_Primas[#All],2,0),"")
A5: 6 | B5: =IFERROR(VLOOKUP(A5,Proveedores[#All],2,0),"") -> Meriggi | C5: TE-10 | D5: =IFERROR(VLOOKUP(C5,Materias_Primas[#All],2,0),"") -> Bistrech 150 cm Ne | E5: 844
A6: 6 | B6: =IFERROR(VLOOKUP(A6,Proveedores[#All],2,0),"") -> Meriggi | C6: TE-11 | D6: =IFERROR(VLOOKUP(C6,Materias_Primas[#All],2,0),"") -> Bistrech 300 cm Ne
A7: 6 | B7: =IFERROR(VLOOKUP(A7,Proveedores[#All],2,0),"") -> Meriggi | C7: TE-15 | D7: =IFERROR(VLOOKUP(C7,Materias_Primas[#All],2,0),"") -> Bistrech 150 cm Ve | E7: 844
A8: 3 | B8: =IFERROR(VLOOKUP(A8,Proveedores[#All],2,0),"") -> Rainbown Publicidad | C8: SE-01 | D8: =IFERROR(VLOOKUP(C8,Materias_Primas[#All],2,0),"") -> Estampado Logo Turb. | E8: 36
B9: =IFERROR(VLOOKUP(A9,Proveedores[#All],2,0),"") | D9: =IFERROR(VLOOKUP(C9,Materias_Primas[#All],2,0),"")
B10: =IFERROR(VLOOKUP(A10,Proveedores[#All],2,0),"") | D10: =IFERROR(VLOOKUP(C10,Materias_Primas[#All],2,0),"")
B11: =IFERROR(VLOOKUP(A11,Proveedores[#All],2,0),"") | D11: =IFERROR(VLOOKUP(C11,Materias_Primas[#All],2,0),"")
B12: =IFERROR(VLOOKUP(A12,Proveedores[#All],2,0),"") | D12: =IFERROR(VLOOKUP(C12,Materias_Primas[#All],2,0),"")
B13: =IFERROR(VLOOKUP(A13,Proveedores[#All],2,0),"") | D13: =IFERROR(VLOOKUP(C13,Materias_Primas[#All],2,0),"")
B14: =IFERROR(VLOOKUP(A14,Proveedores[#All],2,0),"") | D14: =IFERROR(VLOOKUP(C14,Materias_Primas[#All],2,0),"")
B15: =IFERROR(VLOOKUP(A15,Proveedores[#All],2,0),"") | D15: =IFERROR(VLOOKUP(C15,Materias_Primas[#All],2,0),"")
B16: =IFERROR(VLOOKUP(A16,Proveedores[#All],2,0),"") | D16: =IFERROR(VLOOKUP(C16,Materias_Primas[#All],2,0),"")

Sheet Consumo
A1: Producto | B1: Nombre P | C1: Cantidad | D1: MP | E1: Nombre | F1: Cant PR | G1: Cant MP | H1: Cons Unit | I1: ID | J1: Tipo | K1: Consumo | L1: Unidad
A2: ='Receta'!A2 -> TO-07 | B2: =IFERROR(VLOOKUP(A2,Productos[#All],2,0),"") -> Toalla 160x80 Na | C2: =SUMIF(Producción[[#All],[Producto]],A2,Producción[[#All],[Cant]]) -> 2 | D2: ='Receta'!E2 -> TE-01 | E2: =IFERROR(VLOOKUP(D2,Materias_Primas[#All],2,0),"") -> Microfibra Dep 160 Na | F2: ='Receta'!C2 -> 1 | G2: ='Receta'!H2 -> 0.8 | H2: =IFERROR(G2/F2,"") -> 0.8 | I2: 1 | J2: Empanada | K2: =C2*H2 -> 1.6 | L2: =IFERROR(VLOOKUP(D2,Materias_Primas[#All],5,0),"") -> Mts
A3: ='Receta'!A3 -> TO-07 | B3: =IFERROR(VLOOKUP(A3,Productos[#All],2,0),"") -> Toalla 160x80 Na | C3: =SUMIF(Producción[[#All],[Producto]],A3,Producción[[#All],[Cant]]) -> 2 | D3: ='Receta'!E3 -> HI-01 | E3: =IFERROR(VLOOKUP(D3,Materias_Primas[#All],2,0),"") -> Hilo Overlock Verde | F3: ='Receta'!C3 -> 1 | G3: ='Receta'!H3 -> 0.04 | H3: =IFERROR(G3/F3,"") -> 0.04 | I3: 1 | J3: Empanada | K3: =C3*H3 -> 0.08 | L3: =IFERROR(VLOOKUP(D3,Materias_Primas[#All],5,0),"") -> Uni
A4: ='Receta'!A4 -> TO-07 | B4: =IFERROR(VLOOKUP(A4,Productos[#All],2,0),"") -> Toalla 160x80 Na | C4: =SUMIF(Producción[[#All],[Producto]],A4,Producción[[#All],[Cant]]) -> 2 | D4: ='Receta'!E4 -> HI-02 | E4: =IFERROR(VLOOKUP(D4,Materias_Primas[#All],2,0),"") -> Hilo Recta Verde | F4: ='Receta'!C4 -> 1 | G4: ='Receta'!H4 -> 0.04 | H4: =IFERROR(G4/F4,"") -> 0.04 | I4: 1 | J4: Empanada | K4: =C4*H4 -> 0.08 | L4: =IFERROR(VLOOKUP(D4,Materias_Primas[#All],5,0),"") -> Uni
A5: ='Receta'!A5 -> TO-07 | B5: =IFERROR(VLOOKUP(A5,Productos[#All],2,0),"") -> Toalla 160x80 Na | C5: =SUMIF(Producción[[#All],[Producto]],A5,Producción[[#All],[Cant]]) -> 2 | D5: ='Receta'!E5 -> GA-01 | E5: =IFERROR(VLOOKUP(D5,Materias_Primas[#All],2,0),"") -> Locomoción | F5: ='Receta'!C5 -> 1 | G5: ='Receta'!H5 -> 0.1 | H5: =IFERROR(G5/F5,"") -> 0.1 | I5: 1 | J5: Empanada | K5: =C5*H5 -> 0.2 | L5: =IFERROR(VLOOKUP(D5,Materias_Primas[#All],5,0),"") -> Uni
A6: ='Receta'!A6 -> TO-06 | B6: =IFERROR(VLOOKUP(A6,Productos[#All],2,0),"") -> Toalla 160x80 Fu | C6: =SUMIF(Producción[[#All],[Producto]],A6,Producción[[#All],[Cant]]) -> 2 | D6: ='Receta'!E6 -> TE-03 | E6: =IFERROR(VLOOKUP(D6,Materias_Primas[#All],2,0),"") -> Microfibra Dep 160 Fu | F6: ='Receta'!C6 -> 1 | G6: ='Receta'!H6 -> 0.8 | H6: =IFERROR(G6/F6,"") -> 0.8 | I6: 1 | J6: Empanada | K6: =C6*H6 -> 1.6 | L6: =IFERROR(VLOOKUP(D6,Materias_Primas[#All],5,0),"") -> Mts
A7: ='Receta'!A7 -> TO-06 | B7: =IFERROR(VLOOKUP(A7,Productos[#All],2,0),"") -> Toalla 160x80 Fu | C7: =SUMIF(Producción[[#All],[Producto]],A7,Producción[[#All],[Cant]]) -> 2 | D7: ='Receta'!E7 -> HI-01 | E7: =IFERROR(VLOOKUP(D7,Materias_Primas[#All],2,0),"") -> Hilo Overlock Verde | F7: ='Receta'!C7 -> 1 | G7: ='Receta'!H7 -> 0.04 | H7: =IFERROR(G7/F7,"") -> 0.04 | I7: 1 | J7: Empanada | K7: =C7*H7 -> 0.08 | L7: =IFERROR(VLOOKUP(D7,Materias_Primas[#All],5,0),"") -> Uni
A8: ='Receta'!A8 -> TO-06 | B8: =IFERROR(VLOOKUP(A8,Productos[#All],2,0),"") -> Toalla 160x80 Fu | C8: =SUMIF(Producción[[#All],[Producto]],A8,Producción[[#All],[Cant]]) -> 2 | D8: ='Receta'!E8 -> HI-02 | E8: =IFERROR(VLOOKUP(D8,Materias_Primas[#All],2,0),"") -> Hilo Recta Verde | F8: ='Receta'!C8 -> 1 | G8: ='Receta'!H8 -> 0.04 | H8: =IFERROR(G8/F8,"") -> 0.04 | I8: 1 | J8: Empanada | K8: =C8*H8 -> 0.08 | L8: =IFERROR(VLOOKUP(D8,Materias_Primas[#All],5,0),"") -> Uni
A9: ='Receta'!A9 -> TO-06 | B9: =IFERROR(VLOOKUP(A9,Productos[#All],2,0),"") -> Toalla 160x80 Fu | C9: =SUMIF(Producción[[#All],[Producto]],A9,Producción[[#All],[Cant]]) -> 2 | D9: ='Receta'!E9 -> GA-01 | E9: =IFERROR(VLOOKUP(D9,Materias_Primas[#All],2,0),"") -> Locomoción | F9: ='Receta'!C9 -> 1 | G9: ='Receta'!H9 -> 0.1 | H9: =IFERROR(G9/F9,"") -> 0.1 | I9: 1 | J9: Empanada | K9: =C9*H9 -> 0.2 | L9: =IFERROR(VLOOKUP(D9,Materias_Primas[#All],5,0),"") -> Uni
A10: ='Receta'!A10 -> TO-01 | B10: =IFERROR(VLOOKUP(A10,Productos[#All],2,0),"") -> Toalla 160x80 Az | C10: =SUMIF(Producción[[#All],[Producto]],A10,Producción[[#All],[Cant]]) -> 2 | D10: ='Receta'!E10 -> TE-09 | E10: =IFERROR(VLOOKUP(D10,Materias_Primas[#All],2,0),"") -> Microfibra Dep 160 Az | F10: ='Receta'!C10 -> 1 | G10: ='Receta'!H10 -> 0.8 | H10: =IFERROR(G10/F10,"") -> 0.8 | I10: 1 | J10: Empanada | K10: =C10*H10 -> 1.6 | L10: =IFERROR(VLOOKUP(D10,Materias_Primas[#All],5,0),"") -> Mts
A11: ='Receta'!A11 -> TO-01 | B11: =IFERROR(VLOOKUP(A11,Productos[#All],2,0),"") -> Toalla 160x80 Az | C11: =SUMIF(Producción[[#All],[Producto]],A11,Producción[[#All],[Cant]]) -> 2 | D11: ='Receta'!E11 -> HI-01 | E11: =IFERROR(VLOOKUP(D11,Materias_Primas[#All],2,0),"") -> Hilo Overlock Verde | F11: ='Receta'!C11 -> 1 | G11: ='Receta'!H11 -> 0.04 | H11: =IFERROR(G11/F11,"") -> 0.04 | I11: 1 | J11: Empanada | K11: =C11*H11 -> 0.08 | L11: =IFERROR(VLOOKUP(D11,Materias_Primas[#All],5,0),"") -> Uni
A12: ='Receta'!A12 -> TO-01 | B12: =IFERROR(VLOOKUP(A12,Productos[#All],2,0),"") -> Toalla 160x80 Az | C12: =SUMIF(Producción[[#All],[Producto]],A12,Producción[[#All],[Cant]]) -> 2 | D12: ='Receta'!E12 -> HI-02 | E12: =IFERROR(VLOOKUP(D12,Materias_Primas[#All],2,0),"") -> Hilo Recta Verde | F12: ='Receta'!C12 -> 1 | G12: ='Receta'!H12 -> 0.04 | H12: =IFERROR(G12/F12,"") -> 0.04 | I12: 1 | J12: Empanada | K12: =C12*H12 -> 0.08 | L12: =IFERROR(VLOOKUP(D12,Materias_Primas[#All],5,0),"") -> Uni
A13: ='Receta'!A13 -> TO-01 | B13: =IFERROR(VLOOKUP(A13,Productos[#All],2,0),"") -> Toalla 160x80 Az | C13: =SUMIF(Producción[[#All],[Producto]],A13,Producción[[#All],[Cant]]) -> 2 | D13: ='Receta'!E13 -> GA-01 | E13: =IFERROR(VLOOKUP(D13,Materias_Primas[#All],2,0),"") -> Locomoción | F13: ='Receta'!C13 -> 1 | G13: ='Receta'!H13 -> 0.1 | H13: =IFERROR(G13/F13,"") -> 0.1 | I13: 1 | J13: Empanada | K13: =C13*H13 -> 0.2 | L13: =IFERROR(VLOOKUP(D13,Materias_Primas[#All],5,0),"") -> Uni
... A295: ='Receta'!A295 -> 0 | B295: =IFERROR(VLOOKUP(A295,Productos[#All],2,0),"") | C295: =SUMIF(Producción[[#All],[Producto]],A295,Producción[[#All],[Cant]]) -> 0 | D295: ='Receta'!E295 -> 0 | E295: =IFERROR(VLOOKUP(D295,Materias_Primas[#All],2,0),"") | F295: ='Receta'!C295 -> TERMINACIÓN | G295: ='Receta'!H295 -> 0 | H295: =IFERROR(G295/F295,"") | I295: 7 | J295: Empanada | K295: =C295*H295 -> #VALUE! | L295: =IFERROR(VLOOKUP(D295,Materias_Primas[#All],5,0),"")
A296: ='Receta'!A297 -> 0 | B296: =IFERROR(VLOOKUP(A296,Productos[#All],2,0),"") | C296: =SUMIF(Producción[[#All],[Producto]],A296,Producción[[#All],[Cant]]) -> 0 | D296: ='Receta'!E297 -> 0 | E296: =IFERROR(VLOOKUP(D296,Materias_Primas[#All],2,0),"") | F296: ='Receta'!C297 -> PLANCHADO | G296: ='Receta'!H297 -> 0 | H296: =IFERROR(G296/F296,"") | I296: 7 | J296: Empanada | K296: =C296*H296 -> #VALUE! | L296: =IFERROR(VLOOKUP(D296,Materias_Primas[#All],5,0),"")
A297: ='Receta'!A298 -> 0 | B297: =IFERROR(VLOOKUP(A297,Productos[#All],2,0),"") | C297: =SUMIF(Producción[[#All],[Producto]],A297,Producción[[#All],[Cant]]) -> 0 | D297: ='Receta'!E298 -> 1820 | E297: =IFERROR(VLOOKUP(D297,Materias_Primas[#All],2,0),"") | F297: ='Receta'!C298 -> MO | G297: ='Receta'!H298 -> 0 | H297: =IFERROR(G297/F297,"") | I297: 7 | J297: Empanada | K297: =C297*H297 -> #VALUE! | L297: =IFERROR(VLOOKUP(D297,Materias_Primas[#All],5,0),"")
A298: ='Receta'!A299 -> 0 | B298: =IFERROR(VLOOKUP(A298,Productos[#All],2,0),"") | C298: =SUMIF(Producción[[#All],[Producto]],A298,Producción[[#All],[Cant]]) -> 0 | D298: ='Receta'!E299 -> 0 | E298: =IFERROR(VLOOKUP(D298,Materias_Primas[#All],2,0),"") | F298: ='Receta'!C299 -> 0 | G298: ='Receta'!H299 -> 0 | H298: =IFERROR(G298/F298,"") | I298: 7 | J298: Empanada | K298: =C298*H298 -> #VALUE! | L298: =IFERROR(VLOOKUP(D298,Materias_Primas[#All],5,0),"")
A299: ='Receta'!A300 -> 0 | B299: =IFERROR(VLOOKUP(A299,Productos[#All],2,0),"") | C299: =SUMIF(Producción[[#All],[Producto]],A299,Producción[[#All],[Cant]]) -> 0 | D299: ='Receta'!E300 -> 0 | E299: =IFERROR(VLOOKUP(D299,Materias_Primas[#All],2,0),"") | F299: ='Receta'!C300 -> 0 | G299: ='Receta'!H300 -> 0 | H299: =IFERROR(G299/F299,"") | I299: 7 | J299: Empanada | K299: =C299*H299 -> #VALUE! | L299: =IFERROR(VLOOKUP(D299,Materias_Primas[#All],5,0),"")
A300: ='Receta'!A301 -> 0 | B300: =IFERROR(VLOOKUP(A300,Productos[#All],2,0),"") | C300: =SUMIF(Producción[[#All],[Producto]],A300,Producción[[#All],[Cant]]) -> 0 | D300: ='Receta'!E301 -> 0 | E300: =IFERROR(VLOOKUP(D300,Materias_Primas[#All],2,0),"") | F300: ='Receta'!C301 -> 0 | G300: ='Receta'!H301 -> 0 | H300: =IFERROR(G300/F300,"") | I300: 7 | J300: Empanada | K300: =C300*H300 -> #VALUE! | L300: =IFERROR(VLOOKUP(D300,Materias_Primas[#All],5,0),"")
A301: ='Receta'!A302 -> 0 | B301: =IFERROR(VLOOKUP(A301,Productos[#All],2,0),"") | C301: =SUMIF(Producción[[#All],[Producto]],A301,Producción[[#All],[Cant]]) -> 0 | D301: ='Receta'!E302 -> 3200 | E301: =IFERROR(VLOOKUP(D301,Materias_Primas[#All],2,0),"") | F301: ='Receta'!C302 -> 0 | G301: ='Receta'!H302 -> 0 | H301: =IFERROR(G301/F301,"") | I301: 7 | J301: Empanada | K301: =C301*H301 -> #VALUE! | L301: =IFERROR(VLOOKUP(D301,Materias_Primas[#All],5,0),"")
A302: ='Receta'!A303 -> 0 | B302: =IFERROR(VLOOKUP(A302,Productos[#All],2,0),"") | C302: =SUMIF(Producción[[#All],[Producto]],A302,Producción[[#All],[Cant]]) -> 0 | D302: ='Receta'!E303 -> 0 | E302: =IFERROR(VLOOKUP(D302,Materias_Primas[#All],2,0),"") | F302: ='Receta'!C303 -> CORTE | G302: ='Receta'!H303 -> 8 | H302: =IFERROR(G302/F302,"") | I302: 7 | J302: Empanada | K302: =C302*H302 -> #VALUE! | L302: =IFERROR(VLOOKUP(D302,Materias_Primas[#All],5,0),"")
A303: ='Receta'!A304 -> 0 | B303: =IFERROR(VLOOKUP(A303,Productos[#All],2,0),"") | C303: =SUMIF(Producción[[#All],[Producto]],A303,Producción[[#All],[Cant]]) -> 0 | D303: ='Receta'!E304 -> 0 | E303: =IFERROR(VLOOKUP(D303,Materias_Primas[#All],2,0),"") | F303: ='Receta'!C304 -> CONFECCIÓN | G303: ='Receta'!H304 -> 3 | H303: =IFERROR(G303/F303,"") | I303: 7 | J303: Empanada | K303: =C303*H303 -> #VALUE! | L303: =IFERROR(VLOOKUP(D303,Materias_Primas[#All],5,0),"")
A304: ='Receta'!A305 -> 0 | B304: =IFERROR(VLOOKUP(A304,Productos[#All],2,0),"") | C304: =SUMIF(Producción[[#All],[Producto]],A304,Producción[[#All],[Cant]]) -> 0 | D304: ='Receta'!E305 -> 0 | E304: =IFERROR(VLOOKUP(D304,Materias_Primas[#All],2,0),"") | F304: ='Receta'!C305 -> TERMINACIÓN | G304: ='Receta'!H305 -> 0 | H304: =IFERROR(G304/F304,"") | I304: 7 | J304: Empanada | K304: =C304*H304 -> #VALUE! | L304: =IFERROR(VLOOKUP(D304,Materias_Primas[#All],5,0),"")
A305: ='Receta'!A306 -> 0 | B305: =IFERROR(VLOOKUP(A305,Productos[#All],2,0),"") | C305: =SUMIF(Producción[[#All],[Producto]],A305,Producción[[#All],[Cant]]) -> 0 | D305: ='Receta'!E306 -> 0 | E305: =IFERROR(VLOOKUP(D305,Materias_Primas[#All],2,0),"") | F305: ='Receta'!C306 -> PREPARADO | G305: ='Receta'!H306 -> 2 | H305: =IFERROR(G305/F305,"") | I305: 7 | J305: Empanada | K305: =C305*H305 -> #VALUE! | L305: =IFERROR(VLOOKUP(D305,Materias_Primas[#All],5,0),"")
A306: ='Receta'!A307 -> 0 | B306: =IFERROR(VLOOKUP(A306,Productos[#All],2,0),"") | C306: =SUMIF(Producción[[#All],[Producto]],A306,Producción[[#All],[Cant]]) -> 0 | D306: ='Receta'!E307 -> 0 | E306: =IFERROR(VLOOKUP(D306,Materias_Primas[#All],2,0),"") | F306: ='Receta'!C307 -> PLANCHADO | G306: ='Receta'!H307 -> 0 | H306: =IFERROR(G306/F306,"") | I306: 7 | J306: Empanada | K306: =C306*H306 -> #VALUE! | L306: =IFERROR(VLOOKUP(D306,Materias_Primas[#All],5,0),"")
A307: ='Receta'!A308 -> 0 | B307: =IFERROR(VLOOKUP(A307,Productos[#All],2,0),"") | C307: =SUMIF(Producción[[#All],[Producto]],A307,Producción[[#All],[Cant]]) -> 0 | D307: ='Receta'!E308 -> 0 | E307: =IFERROR(VLOOKUP(D307,Materias_Primas[#All],2,0),"") | F307: ='Receta'!C308 -> 0 | G307: ='Receta'!H308 -> 0 | H307: =IFERROR(G307/F307,"") | I307: 7 | J307: Empanada | K307: =C307*H307 -> #VALUE! | L307: =IFERROR(VLOOKUP(D307,Materias_Primas[#All],5,0),"")
... A2746: ='Receta'!A2747 -> 0 | B2746: =IFERROR(VLOOKUP(A2746,Productos[#All],2,0),"") | C2746: =SUMIF(Producción[[#All],[Producto]],A2746,Producción[[#All],[Cant]]) -> 0 | D2746: ='Receta'!E2747 -> 0 | E2746: =IFERROR(VLOOKUP(D2746,Materias_Primas[#All],2,0),"") | F2746: ='Receta'!C2747 -> 0 | G2746: ='Receta'!H2747 -> 0 | H2746: =IFERROR(G2746/F2746,"") | I2746: 92 | J2746: Empanada | K2746: =C2746*H2746 -> #VALUE! | L2746: =IFERROR(VLOOKUP(D2746,Materias_Primas[#All],5,0),"")
A2747: Total | B2747: =IFERROR(VLOOKUP(A2747,Productos[#All],2,0),"") | C2747: =SUMIF(Producción[[#All],[Producto]],A2747,Producción[[#All],[Cant]]) -> 0 | D2747: ='Receta'!E2748 -> 0 | H2747: =IFERROR(G2747/F2747,"") | K2747: =SUBTOTAL(109,Consumo!$K$2:$K$2746) -> #VALUE! | L2747: =IFERROR(VLOOKUP(D2747,Materias_Primas[#All],5,0),"")

Sheet Stock
A1: Código | B1: Materia Prima | C1: Cant Cons | D1: Cant Rbjd | E1: Cant Comp | F1: Stock | G1: Unidad | H1: Costo | I1: Pron Com
A2: ='Materias Primas'!$A2 -> TE-01 | B2: =IFERROR(VLOOKUP(Stock!$A2,Materias_Primas[#All],2,0),"") -> Microfibra Dep 160 Na | C2: =IFERROR(SUMIF(Consumo!$E$2:$E$2746,Stock!$B2,Consumo!$K$2:$K$2746),"") -> 3.265 | D2: =SUMIFS(Compras!$H$11:$H$155,Compras!$G$11:$G$155,Stock!$B2,Compras!$C$11:$C$155,"Ajust Inv") -> 0 | E2: =SUMIFS(Compras!$H$2:$H$155,Compras!$G$2:$G$155,Stock!$B2,Compras!$C$2:$C$155,"Compra") -> 5.85 | F2: =Stock!$E2-Stock!$C2-Stock!$D2 -> 2.585 | G2: =IFERROR(VLOOKUP(Stock!$A2,Materias_Primas[#All],5,0),"") -> Mts | H2: =IFERROR(ROUND(VLOOKUP(Stock!$A2,Materias_Primas[#All],7,0)*Stock!$F2,0),"") -> 2021 | I2: =IFERROR(ROUND(Stock!$F2/(Stock!$C2/(TODAY()-MIN(Producción!$C$2:$C$204))),1),"") -> 107.7
